/Users/szjason72/jobfirst-future/looma_crm_future/looma_crm/tracing.py:31: DeprecationWarning: Call to deprecated method __init__. (Since v1.35, the Jaeger supports OTLP natively. Please use the OTLP exporter instead. Support for this exporter will end July 2023.) -- Deprecated since version 1.16.0.
  jaeger_exporter = JaegerExporter(
2025-09-28 10:57:31,304 - tracing - INFO - Jaeger tracing initialized successfully
2025-09-28 10:57:31,304 - __main__ - INFO - Jaeger tracing initialized successfully
[2025-09-28 10:57:31 +0800] [37379] [INFO] Sanic v23.12.1
2025-09-28 10:57:31,315 - sanic.root - INFO - Sanic v23.12.1
[2025-09-28 10:57:31 +0800] [37379] [INFO] Goin' Fast @ http://0.0.0.0:7500
2025-09-28 10:57:31,315 - sanic.root - INFO - Goin' Fast @ http://0.0.0.0:7500
[2025-09-28 10:57:31 +0800] [37379] [INFO] app: looma_crm
2025-09-28 10:57:31,315 - sanic.root - INFO - app: looma_crm
[2025-09-28 10:57:31 +0800] [37379] [INFO] mode: production, single worker
2025-09-28 10:57:31,315 - sanic.root - INFO - mode: production, single worker
[2025-09-28 10:57:31 +0800] [37379] [INFO] server: sanic, HTTP/1.1
2025-09-28 10:57:31,315 - sanic.root - INFO - server: sanic, HTTP/1.1
[2025-09-28 10:57:31 +0800] [37379] [INFO] python: 3.12.11
2025-09-28 10:57:31,315 - sanic.root - INFO - python: 3.12.11
[2025-09-28 10:57:31 +0800] [37379] [INFO] platform: macOS-15.6.1-arm64-arm-64bit
2025-09-28 10:57:31,315 - sanic.root - INFO - platform: macOS-15.6.1-arm64-arm-64bit
[2025-09-28 10:57:31 +0800] [37379] [INFO] packages: sanic-routing==23.12.0
2025-09-28 10:57:31,315 - sanic.root - INFO - packages: sanic-routing==23.12.0
/Users/szjason72/jobfirst-future/looma_crm_future/looma_crm/tracing.py:31: DeprecationWarning: Call to deprecated method __init__. (Since v1.35, the Jaeger supports OTLP natively. Please use the OTLP exporter instead. Support for this exporter will end July 2023.) -- Deprecated since version 1.16.0.
  jaeger_exporter = JaegerExporter(
2025-09-28 10:57:31,770 - tracing - INFO - Jaeger tracing initialized successfully
2025-09-28 10:57:31,770 - __mp_main__ - INFO - Jaeger tracing initialized successfully
/Users/szjason72/jobfirst-future/looma_crm_future/looma_crm/tracing.py:31: DeprecationWarning: Call to deprecated method __init__. (Since v1.35, the Jaeger supports OTLP natively. Please use the OTLP exporter instead. Support for this exporter will end July 2023.) -- Deprecated since version 1.16.0.
  jaeger_exporter = JaegerExporter(
2025-09-28 10:57:32,230 - tracing - INFO - Jaeger tracing initialized successfully
2025-09-28 10:57:32,230 - __mp_main__ - INFO - Jaeger tracing initialized successfully
/Users/szjason72/zervi-basic/looma_crm_ai_refactoring/venv/lib/python3.12/site-packages/sanic/touchup/schemes/ode.py:70: DeprecationWarning: Attribute s is deprecated and will be removed in Python 3.14; use value instead
  if hasattr(event, "s"):
2025-09-28 10:57:32,250 - __mp_main__ - INFO - 正在初始化Looma CRM服务...
2025-09-28 10:57:32,250 - shared.database.unified_data_access - INFO - 正在初始化统一数据访问层...
2025-09-28 10:57:32,250 - shared.database.unified_data_access - INFO - Neo4j连接初始化成功
2025-09-28 10:57:37,236 - opentelemetry.sdk._shared_internal - ERROR - Exception while exporting Span.
Traceback (most recent call last):
  File "/Users/szjason72/zervi-basic/looma_crm_ai_refactoring/venv/lib/python3.12/site-packages/opentelemetry/sdk/_shared_internal/__init__.py", line 179, in _export
    self._exporter.export(
  File "/Users/szjason72/zervi-basic/looma_crm_ai_refactoring/venv/lib/python3.12/site-packages/opentelemetry/exporter/jaeger/thrift/__init__.py", line 225, in export
    self._agent_client.emit(batch)
  File "/Users/szjason72/zervi-basic/looma_crm_ai_refactoring/venv/lib/python3.12/site-packages/opentelemetry/exporter/jaeger/thrift/send.py", line 95, in emit
    udp_socket.sendto(buff, self.address)
OSError: [Errno 40] Message too long
2025-09-28 10:57:37,294 - shared.database.unified_data_access - WARNING - Weaviate连接初始化失败: Weaviate did not start up in 5 seconds. Either the Weaviate URL http://localhost:8091 is wrong or Weaviate did not start up in the interval given in 'startup_period'.
2025-09-28 10:57:37,306 - shared.database.unified_data_access - INFO - PostgreSQL连接池初始化成功
2025-09-28 10:57:37,306 - shared.database.unified_data_access - INFO - Redis连接初始化成功
2025-09-28 10:57:37,306 - shared.database.unified_data_access - INFO - Elasticsearch连接初始化成功
2025-09-28 10:57:37,313 - shared.database.unified_data_access - INFO - MongoDB连接初始化成功
2025-09-28 10:57:37,313 - shared.database.unified_data_access - INFO - 统一数据访问层初始化完成
2025-09-28 10:57:37,313 - __mp_main__ - INFO - 统一数据访问层初始化完成
2025-09-28 10:57:37,313 - shared.middleware.zervigo_auth_middleware - INFO - Zervigo认证中间件初始化完成
2025-09-28 10:57:37,313 - __mp_main__ - INFO - Zervigo认证中间件初始化完成
2025-09-28 10:57:37,313 - services.zervigo_integration_service - INFO - Zervigo集成服务初始化完成
2025-09-28 10:57:37,313 - __mp_main__ - INFO - Zervigo集成服务初始化完成
2025-09-28 10:57:37,313 - __mp_main__ - INFO - Looma CRM服务初始化完成
[2025-09-28 10:57:37 +0800] [37401] [INFO] Starting worker [37401]
2025-09-28 10:57:37,315 - sanic.server - INFO - Starting worker [37401]
2025-09-28 10:57:37,335 - shared.integration.zervigo_client - ERROR - Request failed: Cannot connect to host localhost:7540 ssl:default [Connection refused]
2025-09-28 10:59:11,371 - shared.integration.zervigo_client - ERROR - Request failed: Cannot connect to host localhost:7540 ssl:default [Connection refused]
2025-09-28 10:59:32,751 - shared.integration.zervigo_client - ERROR - Request failed: Cannot connect to host localhost:7540 ssl:default [Connection refused]
2025-09-28 10:59:32,753 - shared.integration.zervigo_client - ERROR - Request failed: Cannot connect to host localhost:7530 ssl:default [Connection refused]
2025-09-28 10:59:33,638 - shared.integration.zervigo_client - ERROR - Request failed: Cannot connect to host localhost:7540 ssl:default [Connection refused]
2025-09-28 10:59:33,641 - shared.integration.zervigo_client - ERROR - Request failed: Cannot connect to host localhost:7530 ssl:default [Connection refused]
[2025-09-28 11:01:07 +0800] [37379] [INFO] Received signal SIGTERM. Shutting down.
2025-09-28 11:01:07,710 - sanic.root - INFO - Received signal SIGTERM. Shutting down.
[2025-09-28 11:01:07 +0800] [37401] [INFO] Stopping worker [37401]
2025-09-28 11:01:07,712 - sanic.server - INFO - Stopping worker [37401]
[2025-09-28 11:01:07 +0800] [37401] [ERROR] 
Traceback (most recent call last):
  File "/Users/szjason72/zervi-basic/looma_crm_ai_refactoring/venv/lib/python3.12/site-packages/sanic/worker/serve.py", line 117, in worker_serve
    return _serve_http_1(
           ^^^^^^^^^^^^^^
  File "/Users/szjason72/zervi-basic/looma_crm_ai_refactoring/venv/lib/python3.12/site-packages/sanic/server/runners.py", line 301, in _serve_http_1
    _run_server_forever(
  File "/Users/szjason72/zervi-basic/looma_crm_ai_refactoring/venv/lib/python3.12/site-packages/sanic/server/runners.py", line 187, in _run_server_forever
    cleanup()
  File "/Users/szjason72/zervi-basic/looma_crm_ai_refactoring/venv/lib/python3.12/site-packages/sanic/server/runners.py", line 296, in _cleanup
    app.set_serving(False)
  File "/Users/szjason72/zervi-basic/looma_crm_ai_refactoring/venv/lib/python3.12/site-packages/sanic/app.py", line 2430, in set_serving
    self.multiplexer.set_serving(serving)
  File "/Users/szjason72/zervi-basic/looma_crm_ai_refactoring/venv/lib/python3.12/site-packages/sanic/worker/multiplexer.py", line 91, in set_serving
    **self._state._state[self.name],
      ~~~~~~~~~~~~~~~~~~^^^^^^^^^^^
  File "<string>", line 2, in __getitem__
  File "/Users/szjason72/.pyenv/versions/3.12.11/lib/python3.12/multiprocessing/managers.py", line 828, in _callmethod
    kind, result = conn.recv()
                   ^^^^^^^^^^^
  File "/Users/szjason72/.pyenv/versions/3.12.11/lib/python3.12/multiprocessing/connection.py", line 250, in recv
    buf = self._recv_bytes()
          ^^^^^^^^^^^^^^^^^^
  File "/Users/szjason72/.pyenv/versions/3.12.11/lib/python3.12/multiprocessing/connection.py", line 430, in _recv_bytes
    buf = self._recv(4)
          ^^^^^^^^^^^^^
  File "/Users/szjason72/.pyenv/versions/3.12.11/lib/python3.12/multiprocessing/connection.py", line 399, in _recv
    raise EOFError
EOFError
2025-09-28 11:01:07,714 - sanic.error - ERROR - 
Traceback (most recent call last):
  File "/Users/szjason72/zervi-basic/looma_crm_ai_refactoring/venv/lib/python3.12/site-packages/sanic/worker/serve.py", line 117, in worker_serve
    return _serve_http_1(
           ^^^^^^^^^^^^^^
  File "/Users/szjason72/zervi-basic/looma_crm_ai_refactoring/venv/lib/python3.12/site-packages/sanic/server/runners.py", line 301, in _serve_http_1
    _run_server_forever(
  File "/Users/szjason72/zervi-basic/looma_crm_ai_refactoring/venv/lib/python3.12/site-packages/sanic/server/runners.py", line 187, in _run_server_forever
    cleanup()
  File "/Users/szjason72/zervi-basic/looma_crm_ai_refactoring/venv/lib/python3.12/site-packages/sanic/server/runners.py", line 296, in _cleanup
    app.set_serving(False)
  File "/Users/szjason72/zervi-basic/looma_crm_ai_refactoring/venv/lib/python3.12/site-packages/sanic/app.py", line 2430, in set_serving
    self.multiplexer.set_serving(serving)
  File "/Users/szjason72/zervi-basic/looma_crm_ai_refactoring/venv/lib/python3.12/site-packages/sanic/worker/multiplexer.py", line 91, in set_serving
    **self._state._state[self.name],
      ~~~~~~~~~~~~~~~~~~^^^^^^^^^^^
  File "<string>", line 2, in __getitem__
  File "/Users/szjason72/.pyenv/versions/3.12.11/lib/python3.12/multiprocessing/managers.py", line 828, in _callmethod
    kind, result = conn.recv()
                   ^^^^^^^^^^^
  File "/Users/szjason72/.pyenv/versions/3.12.11/lib/python3.12/multiprocessing/connection.py", line 250, in recv
    buf = self._recv_bytes()
          ^^^^^^^^^^^^^^^^^^
  File "/Users/szjason72/.pyenv/versions/3.12.11/lib/python3.12/multiprocessing/connection.py", line 430, in _recv_bytes
    buf = self._recv(4)
          ^^^^^^^^^^^^^
  File "/Users/szjason72/.pyenv/versions/3.12.11/lib/python3.12/multiprocessing/connection.py", line 399, in _recv
    raise EOFError
EOFError
[2025-09-28 11:01:07 +0800] [37379] [ERROR] Experienced exception while trying to serve
Traceback (most recent call last):
  File "/Users/szjason72/zervi-basic/looma_crm_ai_refactoring/venv/lib/python3.12/site-packages/sanic/mixins/startup.py", line 1146, in serve
    manager.run()
  File "/Users/szjason72/zervi-basic/looma_crm_ai_refactoring/venv/lib/python3.12/site-packages/sanic/worker/manager.py", line 189, in run
    self.monitor()
  File "/Users/szjason72/zervi-basic/looma_crm_ai_refactoring/venv/lib/python3.12/site-packages/sanic/worker/manager.py", line 289, in monitor
    cycle = self._poll_monitor()
            ^^^^^^^^^^^^^^^^^^^^
  File "/Users/szjason72/zervi-basic/looma_crm_ai_refactoring/venv/lib/python3.12/site-packages/sanic/worker/manager.py", line 447, in _poll_monitor
    if self.monitor_subscriber.poll(0.1):
       ^^^^^^^^^^^^^^^^^^^^^^^^^^^^^^^^^
  File "/Users/szjason72/.pyenv/versions/3.12.11/lib/python3.12/multiprocessing/connection.py", line 257, in poll
    return self._poll(timeout)
           ^^^^^^^^^^^^^^^^^^^
  File "/Users/szjason72/.pyenv/versions/3.12.11/lib/python3.12/multiprocessing/connection.py", line 440, in _poll
    r = wait([self], timeout)
        ^^^^^^^^^^^^^^^^^^^^^
  File "/Users/szjason72/.pyenv/versions/3.12.11/lib/python3.12/multiprocessing/connection.py", line 1136, in wait
    ready = selector.select(timeout)
            ^^^^^^^^^^^^^^^^^^^^^^^^
  File "/Users/szjason72/.pyenv/versions/3.12.11/lib/python3.12/selectors.py", line 415, in select
    fd_event_list = self._selector.poll(timeout)
                    ^^^^^^^^^^^^^^^^^^^^^^^^^^^^
  File "/Users/szjason72/zervi-basic/looma_crm_ai_refactoring/venv/lib/python3.12/site-packages/sanic/worker/manager.py", line 383, in shutdown_signal
    self.shutdown()
  File "/Users/szjason72/zervi-basic/looma_crm_ai_refactoring/venv/lib/python3.12/site-packages/sanic/worker/manager.py", line 389, in shutdown
    process.terminate()
  File "/Users/szjason72/zervi-basic/looma_crm_ai_refactoring/venv/lib/python3.12/site-packages/sanic/worker/process.py", line 103, in terminate
    self.set_state(ProcessState.TERMINATED, force=True)
  File "/Users/szjason72/zervi-basic/looma_crm_ai_refactoring/venv/lib/python3.12/site-packages/sanic/worker/process.py", line 53, in set_state
    **self.worker_state[self.name],
      ~~~~~~~~~~~~~~~~~^^^^^^^^^^^
  File "<string>", line 2, in __getitem__
  File "/Users/szjason72/.pyenv/versions/3.12.11/lib/python3.12/multiprocessing/managers.py", line 828, in _callmethod
    kind, result = conn.recv()
                   ^^^^^^^^^^^
  File "/Users/szjason72/.pyenv/versions/3.12.11/lib/python3.12/multiprocessing/connection.py", line 250, in recv
    buf = self._recv_bytes()
          ^^^^^^^^^^^^^^^^^^
  File "/Users/szjason72/.pyenv/versions/3.12.11/lib/python3.12/multiprocessing/connection.py", line 430, in _recv_bytes
    buf = self._recv(4)
          ^^^^^^^^^^^^^
  File "/Users/szjason72/.pyenv/versions/3.12.11/lib/python3.12/multiprocessing/connection.py", line 399, in _recv
    raise EOFError
EOFError
2025-09-28 11:01:07,714 - sanic.error - ERROR - Experienced exception while trying to serve
Traceback (most recent call last):
  File "/Users/szjason72/zervi-basic/looma_crm_ai_refactoring/venv/lib/python3.12/site-packages/sanic/mixins/startup.py", line 1146, in serve
    manager.run()
  File "/Users/szjason72/zervi-basic/looma_crm_ai_refactoring/venv/lib/python3.12/site-packages/sanic/worker/manager.py", line 189, in run
    self.monitor()
  File "/Users/szjason72/zervi-basic/looma_crm_ai_refactoring/venv/lib/python3.12/site-packages/sanic/worker/manager.py", line 289, in monitor
    cycle = self._poll_monitor()
            ^^^^^^^^^^^^^^^^^^^^
  File "/Users/szjason72/zervi-basic/looma_crm_ai_refactoring/venv/lib/python3.12/site-packages/sanic/worker/manager.py", line 447, in _poll_monitor
    if self.monitor_subscriber.poll(0.1):
       ^^^^^^^^^^^^^^^^^^^^^^^^^^^^^^^^^
  File "/Users/szjason72/.pyenv/versions/3.12.11/lib/python3.12/multiprocessing/connection.py", line 257, in poll
    return self._poll(timeout)
           ^^^^^^^^^^^^^^^^^^^
  File "/Users/szjason72/.pyenv/versions/3.12.11/lib/python3.12/multiprocessing/connection.py", line 440, in _poll
    r = wait([self], timeout)
        ^^^^^^^^^^^^^^^^^^^^^
  File "/Users/szjason72/.pyenv/versions/3.12.11/lib/python3.12/multiprocessing/connection.py", line 1136, in wait
    ready = selector.select(timeout)
            ^^^^^^^^^^^^^^^^^^^^^^^^
  File "/Users/szjason72/.pyenv/versions/3.12.11/lib/python3.12/selectors.py", line 415, in select
    fd_event_list = self._selector.poll(timeout)
                    ^^^^^^^^^^^^^^^^^^^^^^^^^^^^
  File "/Users/szjason72/zervi-basic/looma_crm_ai_refactoring/venv/lib/python3.12/site-packages/sanic/worker/manager.py", line 383, in shutdown_signal
    self.shutdown()
  File "/Users/szjason72/zervi-basic/looma_crm_ai_refactoring/venv/lib/python3.12/site-packages/sanic/worker/manager.py", line 389, in shutdown
    process.terminate()
  File "/Users/szjason72/zervi-basic/looma_crm_ai_refactoring/venv/lib/python3.12/site-packages/sanic/worker/process.py", line 103, in terminate
    self.set_state(ProcessState.TERMINATED, force=True)
  File "/Users/szjason72/zervi-basic/looma_crm_ai_refactoring/venv/lib/python3.12/site-packages/sanic/worker/process.py", line 53, in set_state
    **self.worker_state[self.name],
      ~~~~~~~~~~~~~~~~~^^^^^^^^^^^
  File "<string>", line 2, in __getitem__
  File "/Users/szjason72/.pyenv/versions/3.12.11/lib/python3.12/multiprocessing/managers.py", line 828, in _callmethod
    kind, result = conn.recv()
                   ^^^^^^^^^^^
  File "/Users/szjason72/.pyenv/versions/3.12.11/lib/python3.12/multiprocessing/connection.py", line 250, in recv
    buf = self._recv_bytes()
          ^^^^^^^^^^^^^^^^^^
  File "/Users/szjason72/.pyenv/versions/3.12.11/lib/python3.12/multiprocessing/connection.py", line 430, in _recv_bytes
    buf = self._recv(4)
          ^^^^^^^^^^^^^
  File "/Users/szjason72/.pyenv/versions/3.12.11/lib/python3.12/multiprocessing/connection.py", line 399, in _recv
    raise EOFError
EOFError
[2025-09-28 11:01:07 +0800] [37379] [INFO] Server Stopped
2025-09-28 11:01:07,719 - sanic.root - INFO - Server Stopped
Traceback (most recent call last):
  File "/Users/szjason72/zervi-basic/looma_crm_ai_refactoring/venv/lib/python3.12/site-packages/sanic/mixins/startup.py", line 1146, in serve
    manager.run()
  File "/Users/szjason72/zervi-basic/looma_crm_ai_refactoring/venv/lib/python3.12/site-packages/sanic/worker/manager.py", line 189, in run
    self.monitor()
  File "/Users/szjason72/zervi-basic/looma_crm_ai_refactoring/venv/lib/python3.12/site-packages/sanic/worker/manager.py", line 289, in monitor
    cycle = self._poll_monitor()
            ^^^^^^^^^^^^^^^^^^^^
  File "/Users/szjason72/zervi-basic/looma_crm_ai_refactoring/venv/lib/python3.12/site-packages/sanic/worker/manager.py", line 447, in _poll_monitor
    if self.monitor_subscriber.poll(0.1):
       ^^^^^^^^^^^^^^^^^^^^^^^^^^^^^^^^^
  File "/Users/szjason72/.pyenv/versions/3.12.11/lib/python3.12/multiprocessing/connection.py", line 257, in poll
    return self._poll(timeout)
           ^^^^^^^^^^^^^^^^^^^
  File "/Users/szjason72/.pyenv/versions/3.12.11/lib/python3.12/multiprocessing/connection.py", line 440, in _poll
    r = wait([self], timeout)
        ^^^^^^^^^^^^^^^^^^^^^
  File "/Users/szjason72/.pyenv/versions/3.12.11/lib/python3.12/multiprocessing/connection.py", line 1136, in wait
    ready = selector.select(timeout)
            ^^^^^^^^^^^^^^^^^^^^^^^^
  File "/Users/szjason72/.pyenv/versions/3.12.11/lib/python3.12/selectors.py", line 415, in select
    fd_event_list = self._selector.poll(timeout)
                    ^^^^^^^^^^^^^^^^^^^^^^^^^^^^
  File "/Users/szjason72/zervi-basic/looma_crm_ai_refactoring/venv/lib/python3.12/site-packages/sanic/worker/manager.py", line 383, in shutdown_signal
    self.shutdown()
  File "/Users/szjason72/zervi-basic/looma_crm_ai_refactoring/venv/lib/python3.12/site-packages/sanic/worker/manager.py", line 389, in shutdown
    process.terminate()
  File "/Users/szjason72/zervi-basic/looma_crm_ai_refactoring/venv/lib/python3.12/site-packages/sanic/worker/process.py", line 103, in terminate
    self.set_state(ProcessState.TERMINATED, force=True)
  File "/Users/szjason72/zervi-basic/looma_crm_ai_refactoring/venv/lib/python3.12/site-packages/sanic/worker/process.py", line 53, in set_state
    **self.worker_state[self.name],
      ~~~~~~~~~~~~~~~~~^^^^^^^^^^^
  File "<string>", line 2, in __getitem__
  File "/Users/szjason72/.pyenv/versions/3.12.11/lib/python3.12/multiprocessing/managers.py", line 828, in _callmethod
    kind, result = conn.recv()
                   ^^^^^^^^^^^
  File "/Users/szjason72/.pyenv/versions/3.12.11/lib/python3.12/multiprocessing/connection.py", line 250, in recv
    buf = self._recv_bytes()
          ^^^^^^^^^^^^^^^^^^
  File "/Users/szjason72/.pyenv/versions/3.12.11/lib/python3.12/multiprocessing/connection.py", line 430, in _recv_bytes
    buf = self._recv(4)
          ^^^^^^^^^^^^^
  File "/Users/szjason72/.pyenv/versions/3.12.11/lib/python3.12/multiprocessing/connection.py", line 399, in _recv
    raise EOFError
EOFError

During handling of the above exception, another exception occurred:

Traceback (most recent call last):
  File "/Users/szjason72/jobfirst-future/looma_crm_future/looma_crm/app.py", line 277, in <module>
    app.run(
  File "/Users/szjason72/zervi-basic/looma_crm_ai_refactoring/venv/lib/python3.12/site-packages/sanic/mixins/startup.py", line 290, in run
    serve(primary=self)  # type: ignore
    ^^^^^^^^^^^^^^^^^^^
  File "/Users/szjason72/zervi-basic/looma_crm_ai_refactoring/venv/lib/python3.12/site-packages/sanic/mixins/startup.py", line 1177, in serve
    while cls._get_process_states(worker_state):
          ^^^^^^^^^^^^^^^^^^^^^^^^^^^^^^^^^^^^^
  File "/Users/szjason72/zervi-basic/looma_crm_ai_refactoring/venv/lib/python3.12/site-packages/sanic/mixins/startup.py", line 1198, in _get_process_states
    for s in worker_state.values()
             ^^^^^^^^^^^^^^^^^^^^^
  File "<string>", line 2, in values
  File "/Users/szjason72/.pyenv/versions/3.12.11/lib/python3.12/multiprocessing/managers.py", line 827, in _callmethod
    conn.send((self._id, methodname, args, kwds))
  File "/Users/szjason72/.pyenv/versions/3.12.11/lib/python3.12/multiprocessing/connection.py", line 206, in send
    self._send_bytes(_ForkingPickler.dumps(obj))
  File "/Users/szjason72/.pyenv/versions/3.12.11/lib/python3.12/multiprocessing/connection.py", line 427, in _send_bytes
    self._send(header + buf)
  File "/Users/szjason72/.pyenv/versions/3.12.11/lib/python3.12/multiprocessing/connection.py", line 384, in _send
    n = write(self._handle, buf)
        ^^^^^^^^^^^^^^^^^^^^^^^^
BrokenPipeError: [Errno 32] Broken pipe
