[2025-09-25 11:05:47 +0800] [4031] [INFO] Sanic v23.12.1
2025-09-25 11:05:47,576 - sanic.root - INFO - Sanic v23.12.1
[2025-09-25 11:05:47 +0800] [4031] [INFO] Goin' Fast @ http://0.0.0.0:8700
2025-09-25 11:05:47,577 - sanic.root - INFO - Goin' Fast @ http://0.0.0.0:8700
[2025-09-25 11:05:47 +0800] [4031] [INFO] app: looma_crm
2025-09-25 11:05:47,577 - sanic.root - INFO - app: looma_crm
[2025-09-25 11:05:47 +0800] [4031] [INFO] mode: production, single worker
2025-09-25 11:05:47,577 - sanic.root - INFO - mode: production, single worker
[2025-09-25 11:05:47 +0800] [4031] [INFO] server: sanic, HTTP/1.1
2025-09-25 11:05:47,577 - sanic.root - INFO - server: sanic, HTTP/1.1
[2025-09-25 11:05:47 +0800] [4031] [INFO] python: 3.12.11
2025-09-25 11:05:47,577 - sanic.root - INFO - python: 3.12.11
[2025-09-25 11:05:47 +0800] [4031] [INFO] platform: macOS-15.6.1-arm64-arm-64bit
2025-09-25 11:05:47,577 - sanic.root - INFO - platform: macOS-15.6.1-arm64-arm-64bit
[2025-09-25 11:05:47 +0800] [4031] [INFO] packages: sanic-routing==23.12.0
2025-09-25 11:05:47,577 - sanic.root - INFO - packages: sanic-routing==23.12.0
[2025-09-25 11:05:47 +0800] [4031] [ERROR] Experienced exception while trying to serve
Traceback (most recent call last):
  File "/Users/szjason72/zervi-basic/looma_crm_ai_refactoring/venv/lib/python3.12/site-packages/sanic/server/socket.py", line 110, in configure_socket
    sock = bind_socket(
           ^^^^^^^^^^^^
  File "/Users/szjason72/zervi-basic/looma_crm_ai_refactoring/venv/lib/python3.12/site-packages/sanic/server/socket.py", line 33, in bind_socket
    sock.bind(location)
OSError: [Errno 48] Address already in use

During handling of the above exception, another exception occurred:

Traceback (most recent call last):
  File "/Users/szjason72/zervi-basic/looma_crm_ai_refactoring/venv/lib/python3.12/site-packages/sanic/mixins/startup.py", line 1048, in serve
    configure_socket(server_info.settings)
  File "/Users/szjason72/zervi-basic/looma_crm_ai_refactoring/venv/lib/python3.12/site-packages/sanic/server/socket.py", line 125, in configure_socket
    raise error
sanic.exceptions.ServerError: Sanic server could not start: [Errno 48] Address already in use.

This may have happened if you are running Sanic in the global scope and not inside of a `if __name__ == "__main__"` block.

See more information: https://sanic.dev/en/guide/deployment/manager.html#how-sanic-server-starts-processes

2025-09-25 11:05:47,900 - sanic.error - ERROR - Experienced exception while trying to serve
Traceback (most recent call last):
  File "/Users/szjason72/zervi-basic/looma_crm_ai_refactoring/venv/lib/python3.12/site-packages/sanic/server/socket.py", line 110, in configure_socket
    sock = bind_socket(
           ^^^^^^^^^^^^
  File "/Users/szjason72/zervi-basic/looma_crm_ai_refactoring/venv/lib/python3.12/site-packages/sanic/server/socket.py", line 33, in bind_socket
    sock.bind(location)
OSError: [Errno 48] Address already in use

During handling of the above exception, another exception occurred:

Traceback (most recent call last):
  File "/Users/szjason72/zervi-basic/looma_crm_ai_refactoring/venv/lib/python3.12/site-packages/sanic/mixins/startup.py", line 1048, in serve
    configure_socket(server_info.settings)
  File "/Users/szjason72/zervi-basic/looma_crm_ai_refactoring/venv/lib/python3.12/site-packages/sanic/server/socket.py", line 125, in configure_socket
    raise error
sanic.exceptions.ServerError: Sanic server could not start: [Errno 48] Address already in use.

This may have happened if you are running Sanic in the global scope and not inside of a `if __name__ == "__main__"` block.

See more information: https://sanic.dev/en/guide/deployment/manager.html#how-sanic-server-starts-processes

[2025-09-25 11:05:47 +0800] [4031] [INFO] Server Stopped
2025-09-25 11:05:47,901 - sanic.root - INFO - Server Stopped
Traceback (most recent call last):
  File "/Users/szjason72/zervi-basic/looma_crm_ai_refactoring/venv/lib/python3.12/site-packages/sanic/server/socket.py", line 110, in configure_socket
    sock = bind_socket(
           ^^^^^^^^^^^^
  File "/Users/szjason72/zervi-basic/looma_crm_ai_refactoring/venv/lib/python3.12/site-packages/sanic/server/socket.py", line 33, in bind_socket
    sock.bind(location)
OSError: [Errno 48] Address already in use

During handling of the above exception, another exception occurred:

Traceback (most recent call last):
  File "/Users/szjason72/zervi-basic/looma_crm_ai_refactoring/venv/lib/python3.12/site-packages/sanic/mixins/startup.py", line 1048, in serve
    configure_socket(server_info.settings)
  File "/Users/szjason72/zervi-basic/looma_crm_ai_refactoring/venv/lib/python3.12/site-packages/sanic/server/socket.py", line 125, in configure_socket
    raise error
sanic.exceptions.ServerError: Sanic server could not start: [Errno 48] Address already in use.

This may have happened if you are running Sanic in the global scope and not inside of a `if __name__ == "__main__"` block.

See more information: https://sanic.dev/en/guide/deployment/manager.html#how-sanic-server-starts-processes


During handling of the above exception, another exception occurred:

Traceback (most recent call last):
  File "/Users/szjason72/jobfirst/looma_crm_pro/looma_crm/app.py", line 240, in <module>
    app.run(
  File "/Users/szjason72/zervi-basic/looma_crm_ai_refactoring/venv/lib/python3.12/site-packages/sanic/mixins/startup.py", line 290, in run
    serve(primary=self)  # type: ignore
    ^^^^^^^^^^^^^^^^^^^
  File "/Users/szjason72/zervi-basic/looma_crm_ai_refactoring/venv/lib/python3.12/site-packages/sanic/mixins/startup.py", line 1177, in serve
    while cls._get_process_states(worker_state):
                                  ^^^^^^^^^^^^
UnboundLocalError: cannot access local variable 'worker_state' where it is not associated with a value
sys:1: ResourceWarning: unclosed <socket.socket fd=13, family=2, type=1, proto=0, laddr=('0.0.0.0', 0)>
