INFO:__main__:ÂêØÂä®Future AI GatewayÊúçÂä°...
[2025-09-28 14:49:18 +0800] [16276] [DEBUG] 

                 Sanic
         Build Fast. Run Fast.


DEBUG:sanic.root:

                 Sanic
         Build Fast. Run Fast.


[2025-09-28 14:49:18 +0800] [16276] [INFO] Sanic v23.12.1
INFO:sanic.root:Sanic v23.12.1
[2025-09-28 14:49:18 +0800] [16276] [INFO] Goin' Fast @ http://0.0.0.0:7510
INFO:sanic.root:Goin' Fast @ http://0.0.0.0:7510
[2025-09-28 14:49:18 +0800] [16276] [INFO] app: future_ai_gateway
INFO:sanic.root:app: future_ai_gateway
[2025-09-28 14:49:18 +0800] [16276] [INFO] mode: debug, single worker
INFO:sanic.root:mode: debug, single worker
[2025-09-28 14:49:18 +0800] [16276] [INFO] server: sanic, HTTP/1.1
INFO:sanic.root:server: sanic, HTTP/1.1
[2025-09-28 14:49:18 +0800] [16276] [INFO] python: 3.12.11
INFO:sanic.root:python: 3.12.11
[2025-09-28 14:49:18 +0800] [16276] [INFO] platform: macOS-15.6.1-arm64-arm-64bit
INFO:sanic.root:platform: macOS-15.6.1-arm64-arm-64bit
[2025-09-28 14:49:18 +0800] [16276] [INFO] packages: sanic-routing==23.12.0
INFO:sanic.root:packages: sanic-routing==23.12.0
[2025-09-28 14:49:18 +0800] [16276] [ERROR] Experienced exception while trying to serve
Traceback (most recent call last):
  File "/Users/szjason72/zervi-basic/looma_crm_ai_refactoring/venv/lib/python3.12/site-packages/sanic/server/socket.py", line 110, in configure_socket
    sock = bind_socket(
           ^^^^^^^^^^^^
  File "/Users/szjason72/zervi-basic/looma_crm_ai_refactoring/venv/lib/python3.12/site-packages/sanic/server/socket.py", line 33, in bind_socket
    sock.bind(location)
OSError: [Errno 48] Address already in use

During handling of the above exception, another exception occurred:

Traceback (most recent call last):
  File "/Users/szjason72/zervi-basic/looma_crm_ai_refactoring/venv/lib/python3.12/site-packages/sanic/mixins/startup.py", line 1048, in serve
    configure_socket(server_info.settings)
  File "/Users/szjason72/zervi-basic/looma_crm_ai_refactoring/venv/lib/python3.12/site-packages/sanic/server/socket.py", line 125, in configure_socket
    raise error
sanic.exceptions.ServerError: Sanic server could not start: [Errno 48[2025-09-28 14:49:26 +0800] - (sanic.access)[INFO][127.0.0.1:50464]: GET http://localhost:7510/health  200 132
INFO:sanic.access:
[2025-09-28 15:27:34 +0800] - (sanic.access)[INFO][127.0.0.1:49723]: GET http://localhost:7510/health  200 132
INFO:sanic.access:
[2025-09-28 15:36:09 +0800] - (sanic.access)[INFO][127.0.0.1:50146]: GET http://localhost:7510/health  200 132
INFO:sanic.access:
[2025-09-28 15:40:48 +0800] - (sanic.access)[INFO][127.0.0.1:49403]: GET http://localhost:7510/health  200 132
INFO:sanic.access:
[2025-09-28 15:44:26 +0800] - (sanic.access)[INFO][127.0.0.1:62792]: GET http://localhost:7510/health  200 132
INFO:sanic.access:
[2025-09-28 15:44:26 +0800] - (sanic.access)[INFO][127.0.0.1:62807]: GET http://localhost:7510/health  200 132
INFO:sanic.access:
[2025-09-28 15:47:34 +0800] - (sanic.access)[INFO][127.0.0.1:51426]: GET http://localhost:7510/health  200 132
INFO:sanic.access:
[2025-09-28 15:47:34 +0800] - (sanic.access)[INFO][127.0.0.1:51471]: GET http://localhost:7510/health  200 132
INFO:sanic.access:
[2025-09-28 16:01:47 +0800] - (sanic.access)[INFO][127.0.0.1:52247]: GET http://localhost:7510/health  200 132
INFO:sanic.access:
[2025-09-28 16:01:47 +0800] - (sanic.access)[INFO][127.0.0.1:52292]: GET http://localhost:7510/health  200 132
INFO:sanic.access:
[2025-09-28 16:07:52 +0800] - (sanic.access)[INFO][127.0.0.1:59909]: GET http://localhost:7510/health  200 132
INFO:sanic.access:
[2025-09-28 16:23:58 +0800] - (sanic.access)[INFO][127.0.0.1:60141]: GET http://localhost:7510/health  200 132
INFO:sanic.access:
[2025-09-28 16:28:48 +0800] - (sanic.access)[INFO][127.0.0.1:61877]: GET http://localhost:7510/health  200 132
INFO:sanic.access:
[2025-09-28 16:36:02 +0800] - (sanic.access)[INFO][127.0.0.1:56073]: GET http://localhost:7510/health  200 132
INFO:sanic.access:
[2025-09-28 16:38:54 +0800] - (sanic.access)[INFO][127.0.0.1:55460]: GET http://localhost:7510/health  200 132
INFO:sanic.access:
[2025-09-28 19:58:11 +0800] - (sanic.access)[INFO][127.0.0.1:64383]: GET http://localhost:7510/health  200 132
INFO:sanic.access:
[2025-09-28 19:59:19 +0800] - (sanic.access)[INFO][127.0.0.1:51104]: GET http://localhost:7510/health  200 132
INFO:sanic.access:
[2025-09-28 20:15:12 +0800] - (sanic.access)[INFO][127.0.0.1:64104]: GET http://localhost:7510/health  200 132
INFO:sanic.access:
[2025-09-28 20:15:26 +0800] [14400] [INFO] Stopping worker [14400]
[2025-09-28 20:15:26 +0800] [14371] [INFO] Received signal SIGTERM. Shutting down.
INFO:sanic.server:Stopping worker [14400]
INFO:sanic.root:Received signal SIGTERM. Shutting down.
[2025-09-28 20:15:26 +0800] [14371] [DEBUG] [34mTerminating a process: [1m[38;2;255;13;104mSanic-Server-0-0 [34m[14400][0m
DEBUG:sanic.root:[34mTerminating a process: [1m[38;2;255;13;104mSanic-Server-0-0 [34m[14400][0m
[2025-09-28 20:15:26 +0800] [14400] [INFO] Worker complete [14400]
INFO:sanic.server:Worker complete [14400]
[2025-09-28 20:15:26 +0800] [14371] [INFO] Server Stopped
INFO:sanic.root:Server Stopped
[2025-09-28 20:15:26 +0800] [14371] [DEBUG] Sayonara
DEBUG:sanic.root:Sayonara
 in <module>
    app.run(
  File "/Users/szjason72/zervi-basic/looma_crm_ai_refactoring/venv/lib/python3.12/site-packages/sanic/mixins/startup.py", line 290, in run
    serve(primary=self)  # type: ignore
    ^^^^^^^^^^^^^^^^^^^
  File "/Users/szjason72/zervi-basic/looma_crm_ai_refactoring/venv/lib/python3.12/site-packages/sanic/mixins/startup.py", line 1177, in serve
    while cls._get_process_states(worker_state):
                                  ^^^^^^^^^^^^
UnboundLocalError: cannot access local variable 'worker_state' where it is not associated with a value
